Workbook

Sheet data_cleaning_&_preparation
B2: Missing Value Check | T2: DATA FORMATTING
B4: Column | C4: Total Rows | D4: Missing | E4: Missing % | F4: Status | H4: order_id | I4: order_date | J4: customer_id | K4: product_id | L4: payment_method | M4: courier | N4: order_status | P4: courier | T4: order_date | U4: 45745 | W4: 45745
B5: promo_code | C5: 1200 | D5: 8 | E5: 0.0066666667 | F5: TRUE | H5: ORD00160 | I5: 45758 | J5: CUST0186 | K5: P004 | L5: Credit Card | N5: Delivered | P5: UNKNOWN | T5: unit_price | U5: 200000 | W5: 200000
B6: courier | C6: 1200 | D6: 8 | E6: 0.0066666667 | F6: TRUE | H6: ORD00158 | I6: 45812 | J6: CUST0066 | K6: P041 | L6: E-Wallet | N6: Delivered | P6: UNKNOWN | T6: gross_sales | U6: 400000 | W6: 400000
B7: order_id | C7: 1200 | D7: 0 | E7: 0 | F7: FALSE | H7: ORD00130 | I7: 45688 | J7: CUST0334 | K7: P020 | L7: COD | N7: Delivered | P7: UNKNOWN | T7: discount | U7: 0 | W7: 0
B8: gender | C8: 1200 | D8: 0 | E8: 0 | F8: FALSE | H8: ORD00420 | I8: 45759 | J8: CUST0192 | K8: P051 | L8: E-Wallet | N8: Delivered | P8: UNKNOWN | T8: shipping_cost | U8: 10000 | W8: 10000
B9: customer_name | C9: 1200 | D9: 0 | E9: 0 | F9: FALSE | H9: ORD00562 | I9: 45833 | J9: CUST0048 | K9: P032 | L9: Bank Transfer | N9: Shipped | P9: UNKNOWN | T9: total_amount | U9: 410000 | W9: 410000
B10: brand | C10: 1200 | D10: 0 | E10: 0 | F10: FALSE | H10: ORD00577 | I10: 45709 | J10: CUST0285 | K10: P021 | L10: Bank Transfer | N10: Delivered | P10: UNKNOWN | T10: month | U10: 45717 | W10: 45717
B11: category | C11: 1200 | D11: 0 | E11: 0 | F11: FALSE | H11: ORD00664 | I11: 45803 | J11: CUST0057 | K11: P019 | L11: COD | N11: Delivered | P11: UNKNOWN | T11: net_sales | U11: 45717 | W11: 45717
B12: product_name | C12: 1200 | D12: 0 | E12: 0 | F12: FALSE | H12: ORD00978 | I12: 45719 | J12: CUST0287 | K12: P052 | L12: Credit Card | N12: Delivered | P12: UNKNOWN
B13: net_sales | C13: 1200 | D13: 0 | E13: 0 | F13: FALSE
B14: is_delivered | C14: 1200 | D14: 0 | E14: 0 | F14: FALSE | H14: order_id | I14: order_date | J14: customer_id | K14: product_id | L14: quantity | M14: unit_price | N14: gross_sales | O14: promo_code | P14: discount | R14: promo_code | T14: New Column
B15: month | C15: 1200 | D15: 0 | E15: 0 | F15: FALSE | H15: ORD00125 | I15: 45706 | J15: CUST0042 | K15: P038 | L15: 1 | M15: 35000 | N15: 35000 | P15: 3500 | R15: DISC10
B16: order_status | C16: 1200 | D16: 0 | E16: 0 | F16: FALSE | H16: ORD00139 | I16: 45769 | J16: CUST0252 | K16: P018 | L16: 1 | M16: 500000 | N16: 500000 | P16: 0 | R16: NONE | T16: revenue | U16: Realized revenue generated only from orders with a Delivered status.
B17: payment_method | C17: 1200 | D17: 0 | E17: 0 | F17: FALSE | H17: ORD00200 | I17: 45734 | J17: CUST0207 | K17: P018 | L17: 1 | M17: 500000 | N17: 500000 | P17: 0 | R17: NONE
B18: total_amount | C18: 1200 | D18: 0 | E18: 0 | F18: FALSE | H18: ORD00518 | I18: 45710 | J18: CUST0330 | K18: P059 | L18: 4 | M18: 75000 | N18: 300000 | P18: 0 | R18: NONE
B19: shipping_cost | C19: 1200 | D19: 0 | E19: 0 | F19: FALSE | H19: ORD00656 | I19: 45678 | J19: CUST0092 | K19: P016 | L19: 3 | M19: 150000 | N19: 450000 | P19: 45000 | R19: DISC10
B20: discount | C20: 1200 | D20: 0 | E20: 0 | F20: FALSE | H20: ORD00891 | I20: 45661 | J20: CUST0076 | K20: P009 | L20: 2 | M20: 300000 | N20: 600000 | P20: 0 | R20: NONE
B21: gross_sales | C21: 1200 | D21: 0 | E21: 0 | F21: FALSE | H21: ORD00905 | I21: 45801 | J21: CUST0009 | K21: P013 | L21: 2 | M21: 75000 | N21: 150000 | P21: 15000 | R21: DISC10
B22: unit_price | C22: 1200 | D22: 0 | E22: 0 | F22: FALSE | H22: ORD01179 | I22: 45777 | J22: CUST0230 | K22: P006 | L22: 2 | M22: 500000 | N22: 1000000 | P22: 0 | R22: NONE
B23: quantity | C23: 1200 | D23: 0 | E23: 0 | F23: FALSE
B24: product_id | C24: 1200 | D24: 0 | E24: 0 | F24: FALSE | H24: Duplicate Check
B25: customer_id | C25: 1200 | D25: 0 | E25: 0 | F25: FALSE
B26: order_date | C26: 1200 | D26: 0 | E26: 0 | F26: FALSE | H26: Check Item | I26: Table | J26: Key | K26: Total Row | L26: Unique Value | M26: Status
B27: city | C27: 1200 | D27: 0 | E27: 0 | F27: FALSE | H27: Duplicate Order ID | I27: Orders | J27: order_id | K27: =COUNTA(orders[order_id]) -> 1200 | L27: =COUNTA(_xlfn.UNIQUE(orders[order_id])) -> 1200 | M27: =IF(K27=L27,"Unique","Duplicate") -> Unique
B28: customer_segment | C28: 1200 | D28: 0 | E28: 0 | F28: FALSE | H28: Duplicate Customer Id | I28: Customers | J28: customer_id | K28: =COUNTA(customers[customer_id]) -> 350 | L28: =COUNTA(_xlfn.UNIQUE(customers[customer_id])) -> 350 | M28: =IF(K28=L28,"Unique","Duplicate") -> Unique
H29: Duplicate Product ID | I29: Products | J29: product_id | K29: =COUNTA(products[product_id]) -> 60 | L29: =COUNTA(_xlfn.UNIQUE(products[product_id])) -> 60 | M29: =IF(K29=L29,"Unique","Duplicate") -> Unique

Sheet clean
A1: order_id | B1: order_date | C1: customer_id | D1: product_id | E1: quantity | F1: unit_price | G1: gross_sales | H1: promo_code | I1: discount | J1: shipping_cost | K1: total_amount | L1: payment_method | M1: courier | N1: order_status | O1: month | P1: is_delivered | Q1: net_sales | R1: product_name | S1: category | T1: brand | U1: customer_name | V1: gender | W1: city | X1: customer_segment | Y1: revenue
A2: ORD00062 | B2: 45838 | C2: CUST0024 | D2: P060 | E2: 1 | F2: 150000 | G2: 150000 | H2: NONE | I2: 0 | J2: 10000 | K2: 160000 | L2: Credit Card | M2: JNE | N2: Delivered | O2: 45809 | P2: Yes | Q2: 150000 | R2: Buku Sejarah & Peradaban Dunia | S2: Books | T2: Insight | U2: Rafi Pangestu | V2: Female | W2: Solo | X2: Silver | Y2: =IF(clean[[#This Row],[is_delivered]]="Yes",clean[[#This Row],[net_sales]],0 ) -> 150000
A3: ORD00246 | B3: 45838 | C3: CUST0219 | D3: P018 | E3: 2 | F3: 500000 | G3: 1000000 | H3: NEWUSER | I3: 100000 | J3: 20000 | K3: 920000 | L3: Credit Card | M3: AnterAja | N3: Processing | O3: 45809 | P3: No | Q3: 900000 | R3: Buku Keuangan & Manajemen Investasi | S3: Books | T3: Insight | U3: Laura Dian Permadi | V3: Male | W3: Yogyakarta | X3: Bronze | Y3: =IF(clean[[#This Row],[is_delivered]]="Yes",clean[[#This Row],[net_sales]],0 ) -> 0
A4: ORD00048 | B4: 45838 | C4: CUST0170 | D4: P036 | E4: 4 | F4: 150000 | G4: 600000 | H4: NEWUSER | I4: 60000 | J4: 15000 | K4: 555000 | L4: Bank Transfer | M4: JNE | N4: Shipped | O4: 45809 | P4: No | Q4: 540000 | R4: Buku Kepemimpinan & Manajemen Tim | S4: Books | T4: Insight | U4: Rosa Dwi Laksono Wulandari | V4: Male | W4: Tangerang | X4: Bronze | Y4: =IF(clean[[#This Row],[is_delivered]]="Yes",clean[[#This Row],[net_sales]],0 ) -> 0
A5: ORD00428 | B5: 45838 | C5: CUST0044 | D5: P026 | E5: 4 | F5: 200000 | G5: 800000 | H5: DISC15 | I5: 120000 | J5: 25000 | K5: 705000 | L5: COD | M5: AnterAja | N5: Delivered | O5: 45809 | P5: Yes | Q5: 680000 | R5: Hijab Segiempat Premium Silk | S5: Fashion | T5: Modest | U5: Mia Santoso | V5: Female | W5: Surabaya | X5: Gold | Y5: =IF(clean[[#This Row],[is_delivered]]="Yes",clean[[#This Row],[net_sales]],0 ) -> 680000
A6: ORD00434 | B6: 45838 | C6: CUST0311 | D6: P037 | E6: 1 | F6: 100000 | G6: 100000 | H6: NEWUSER | I6: 10000 | J6: 15000 | K6: 105000 | L6: Bank Transfer | M6: JNE | N6: Returned | O6: 45809 | P6: No | Q6: 90000 | R6: Speaker Bluetooth Portable Bass | S6: Electronics | T6: Atech | U6: Fikri Herlambang | V6: Female | W6: Tangerang | X6: Gold | Y6: =IF(clean[[#This Row],[is_delivered]]="Yes",clean[[#This Row],[net_sales]],0 ) -> 0
A7: ORD00750 | B7: 45838 | C7: CUST0323 | D7: P054 | E7: 1 | F7: 100000 | G7: 100000 | H7: NEWUSER | I7: 10000 | J7: 30000 | K7: 120000 | L7: Credit Card | M7: JNE | N7: Cancelled | O7: 45809 | P7: No | Q7: 90000 | R7: Buku Produktivitas & Manajemen Waktu | S7: Books | T7: Insight | U7: Oscar Bintang Maulana | V7: Female | W7: Surabaya | X7: Bronze | Y7: =IF(clean[[#This Row],[is_delivered]]="Yes",clean[[#This Row],[net_sales]],0 ) -> 0
A8: ORD00799 | B8: 45838 | C8: CUST0310 | D8: P020 | E8: 1 | F8: 75000 | G8: 75000 | H8: DISC15 | I8: 11250 | J8: 15000 | K8: 78750 | L8: E-Wallet | M8: SiCepat | N8: Cancelled | O8: 45809 | P8: No | Q8: 63750 | R8: Jaket Hoodie Oversize Soft | S8: Fashion | T8: Modest | U8: Sheila Bayu Kusnadi | V8: Male | W8: Malang | X8: Gold | Y8: =IF(clean[[#This Row],[is_delivered]]="Yes",clean[[#This Row],[net_sales]],0 ) -> 0
A9: ORD00951 | B9: 45838 | C9: CUST0317 | D9: P046 | E9: 2 | F9: 100000 | G9: 200000 | H9: NONE | I9: 0 | J9: 10000 | K9: 210000 | L9: Bank Transfer | M9: SiCepat | N9: Delivered | O9: 45809 | P9: Yes | Q9: 200000 | R9: Toner Wajah Hydrating Glow | S9: Beauty | T9: GlowUp | U9: Elang Hidayat | V9: Female | W9: Tangerang | X9: Silver | Y9: =IF(clean[[#This Row],[is_delivered]]="Yes",clean[[#This Row],[net_sales]],0 ) -> 200000
A10: ORD00960 | B10: 45838 | C10: CUST0107 | D10: P016 | E10: 1 | F10: 150000 | G10: 150000 | H10: NONE | I10: 0 | J10: 15000 | K10: 165000 | L10: Bank Transfer | M10: SiCepat | N10: Delivered | O10: 45809 | P10: Yes | Q10: 150000 | R10: Sunscreen SPF 50 PA+++ Light | S10: Beauty | T10: GlowUp | U10: Indra Kurnia | V10: Female | W10: Tangerang | X10: Bronze | Y10: =IF(clean[[#This Row],[is_delivered]]="Yes",clean[[#This Row],[net_sales]],0 ) -> 150000
A11: ORD01108 | B11: 45838 | C11: CUST0170 | D11: P055 | E11: 2 | F11: 300000 | G11: 600000 | H11: NONE | I11: 0 | J11: 30000 | K11: 630000 | L11: E-Wallet | M11: JNE | N11: Processing | O11: 45809 | P11: No | Q11: 600000 | R11: Keyboard Mechanical RGB Light | S11: Electronics | T11: Atech | U11: Rosa Dwi Laksono Wulandari | V11: Male | W11: Tangerang | X11: Bronze | Y11: =IF(clean[[#This Row],[is_delivered]]="Yes",clean[[#This Row],[net_sales]],0 ) -> 0
A12: ORD00659 | B12: 45837 | C12: CUST0172 | D12: P045 | E12: 1 | F12: 100000 | G12: 100000 | H12: NONE | I12: 0 | J12: 30000 | K12: 130000 | L12: COD | M12: SiCepat | N12: Delivered | O12: 45809 | P12: Yes | Q12: 100000 | R12: Diffuser Aromaterapi Ultrasonik | S12: Home | T12: Casa | U12: Miko Anjani Wulandari | V12: Female | W12: Solo | X12: Bronze | Y12: =IF(clean[[#This Row],[is_delivered]]="Yes",clean[[#This Row],[net_sales]],0 ) -> 100000
A13: ORD00826 | B13: 45837 | C13: CUST0171 | D13: P039 | E13: 1 | F13: 35000 | G13: 35000 | H13: NONE | I13: 0 | J13: 10000 | K13: 45000 | L13: Bank Transfer | M13: SiCepat | N13: Delivered | O13: 45809 | P13: Yes | Q13: 35000 | R13: Rak Sepatu Minimalis Susun | S13: Home | T13: Casa | U13: Aulia Citra Kusuma Cahyani | V13: Female | W13: Tangerang | X13: Bronze | Y13: =IF(clean[[#This Row],[is_delivered]]="Yes",clean[[#This Row],[net_sales]],0 ) -> 35000
... A1201: ORD01121 | B1201: 45658 | C1201: CUST0244 | D1201: P034 | E1201: 2 | F1201: 50000 | G1201: 100000 | H1201: NONE | I1201: 0 | J1201: 25000 | K1201: 125000 | L1201: Bank Transfer | M1201: JNE | N1201: Delivered | O1201: 45658 | P1201: Yes | Q1201: 100000 | R1201: Masker Wajah Sheet Mask Hydra | S1201: Beauty | T1201: GlowUp | U1201: Sheila Rizki Setiawan | V1201: Female | W1201: Depok | X1201: Bronze | Y1201: =IF(clean[[#This Row],[is_delivered]]="Yes",clean[[#This Row],[net_sales]],0 ) -> 100000

Sheet raw
A1: order_id | B1: order_date | C1: customer_id | D1: product_id | E1: quantity | F1: unit_price | G1: gross_sales | H1: promo_code | I1: discount | J1: shipping_cost | K1: total_amount | L1: payment_method | M1: courier | N1: order_status | O1: month | P1: is_delivered | Q1: net_sales | R1: product_name | S1: category | T1: brand | U1: customer_name | V1: gender | W1: city | X1: customer_segment
A2: ORD00001 | B2: 45745 | C2: CUST0161 | D2: P049 | E2: 2 | F2: 200000 | G2: 400000 | H2: NONE | I2: 0 | J2: 10000 | K2: 410000 | L2: Credit Card | M2: AnterAja | N2: Delivered | O2: 45717 | P2: Yes | Q2: 400000 | R2: Webcam Full HD 1080p | S2: Electronics | T2: Atech | U2: Agung Nur Wijaya | V2: Male | W2: Yogyakarta | X2: Silver
A3: ORD00067 | B3: 45805 | C3: CUST0161 | D3: P010 | E3: 1 | F3: 50000 | G3: 50000 | H3: NEWUSER | I3: 5000 | J3: 10000 | K3: 55000 | L3: E-Wallet | M3: JNE | N3: Delivered | O3: 45778 | P3: Yes | Q3: 45000 | R3: Facial Wash Foam Mild Cleanser | S3: Beauty | T3: GlowUp | U3: Agung Nur Wijaya | V3: Male | W3: Yogyakarta | X3: Silver
A4: ORD00288 | B4: 45765 | C4: CUST0161 | D4: P017 | E4: 1 | F4: 100000 | G4: 100000 | H4: DISC15 | I4: 15000 | J4: 10000 | K4: 95000 | L4: COD | M4: AnterAja | N4: Shipped | O4: 45748 | P4: No | Q4: 85000 | R4: Tali Skipping Adjustable Speed | S4: Sports | T4: Active | U4: Agung Nur Wijaya | V4: Male | W4: Yogyakarta | X4: Silver
A5: ORD00002 | B5: 45738 | C5: CUST0084 | D5: P041 | E5: 1 | F5: 75000 | G5: 75000 | H5: FLASHSALE | I5: 15000 | J5: 10000 | K5: 70000 | L5: COD | M5: SiCepat | N5: Delivered | O5: 45717 | P5: Yes | Q5: 60000 | R5: Raket Bulutangkis Carbon Light | S5: Sports | T5: Active | U5: Vera Pratama | V5: Female | W5: Bekasi | X5: Bronze
A6: ORD00071 | B6: 45719 | C6: CUST0084 | D6: P047 | E6: 1 | F6: 500000 | G6: 500000 | H6: DISC10 | I6: 50000 | J6: 15000 | K6: 465000 | L6: Credit Card | M6: AnterAja | N6: Delivered | O6: 45717 | P6: Yes | Q6: 450000 | R6: Bola Basket Indoor Outdoor | S6: Sports | T6: Active | U6: Vera Pratama | V6: Female | W6: Bekasi | X6: Bronze
A7: ORD00172 | B7: 45688 | C7: CUST0084 | D7: P024 | E7: 1 | F7: 500000 | G7: 500000 | H7: NONE | I7: 0 | J7: 25000 | K7: 525000 | L7: Bank Transfer | M7: AnterAja | N7: Returned | O7: 45658 | P7: No | Q7: 500000 | R7: Buku Novel Fiksi Inspiratif Terbaik | S7: Books | T7: Insight | U7: Vera Pratama | V7: Female | W7: Bekasi | X7: Bronze
A8: ORD00181 | B8: 45662 | C8: CUST0002 | D8: P022 | E8: 1 | F8: 150000 | G8: 150000 | H8: DISC10 | I8: 15000 | J8: 25000 | K8: 160000 | L8: E-Wallet | M8: AnterAja | N8: Delivered | O8: 45658 | P8: Yes | Q8: 135000 | R8: Moisturizing Gel Aloe Vera | S8: Beauty | T8: GlowUp | U8: Kevin Rizki Pangestu Mahendra | V8: Male | W8: Depok | X8: Bronze
A9: ORD00032 | B9: 45827 | C9: CUST0108 | D9: P002 | E9: 4 | F9: 100000 | G9: 400000 | H9: NEWUSER | I9: 40000 | J9: 30000 | K9: 390000 | L9: COD | M9: SiCepat | N9: Delivered | O9: 45809 | P9: Yes | Q9: 360000 | R9: Kemeja Casual Slim Fit | S9: Fashion | T9: Modest | U9: Surya Kusuma | V9: Male | W9: Solo | X9: Bronze
A10: ORD00244 | B10: 45705 | C10: CUST0108 | D10: P044 | E10: 2 | F10: 500000 | G10: 1000000 | H10: DISC10 | I10: 100000 | J10: 20000 | K10: 920000 | L10: E-Wallet | M10: J&T | N10: Processing | O10: 45689 | P10: No | Q10: 900000 | R10: Celana Jeans Stretch Slim | S10: Fashion | T10: Modest | U10: Surya Kusuma | V10: Male | W10: Solo | X10: Bronze
A11: ORD00035 | B11: 45834 | C11: CUST0003 | D11: P045 | E11: 3 | F11: 100000 | G11: 300000 | H11: NONE | I11: 0 | J11: 10000 | K11: 310000 | L11: COD | M11: J&T | N11: Delivered | O11: 45809 | P11: Yes | Q11: 300000 | R11: Diffuser Aromaterapi Ultrasonik | S11: Home | T11: Casa | U11: Sania Maulana | V11: Male | W11: Surabaya | X11: Gold
A12: ORD00072 | B12: 45679 | C12: CUST0003 | D12: P041 | E12: 2 | F12: 75000 | G12: 150000 | H12: DISC10 | I12: 15000 | J12: 25000 | K12: 160000 | L12: Bank Transfer | M12: J&T | N12: Shipped | O12: 45658 | P12: No | Q12: 135000 | R12: Raket Bulutangkis Carbon Light | S12: Sports | T12: Active | U12: Sania Maulana | V12: Male | W12: Surabaya | X12: Gold
A13: ORD00120 | B13: 45793 | C13: CUST0003 | D13: P016 | E13: 3 | F13: 150000 | G13: 450000 | H13: NONE | I13: 0 | J13: 25000 | K13: 475000 | L13: E-Wallet | M13: AnterAja | N13: Delivered | O13: 45778 | P13: Yes | Q13: 450000 | R13: Sunscreen SPF 50 PA+++ Light | S13: Beauty | T13: GlowUp | U13: Sania Maulana | V13: Male | W13: Surabaya | X13: Gold
... A20: ORD00046 | B20: 45772 | C20: CUST0186 | D20: P003 | E20: 1 | F20: 150000 | G20: 150000 | H20: NEWUSER | I20: 15000 | J20: 20000 | K20: 155000 | L20: COD | M20: JNE | N20: Delivered | O20: 45748 | P20: Yes | Q20: 135000 | R20: Sprei Katun Jepang Soft | S20: Home | T20: Casa | U20: Deni Adi Irawan Nugroho | V20: Female | W20: Malang | X20: Gold
A21: ORD00160 | B21: 45758 | C21: CUST0186 | D21: P004 | E21: 4 | F21: 300000 | G21: 1200000 | H21: NONE | I21: 0 | J21: 15000 | K21: 1215000 | L21: Credit Card | N21: Delivered | O21: 45748 | P21: Yes | Q21: 1200000 | R21: Serum Wajah Brightening Vitamin C | S21: Beauty | T21: GlowUp | U21: Deni Adi Irawan Nugroho | V21: Female | W21: Malang | X21: Gold
A22: ORD00265 | B22: 45836 | C22: CUST0186 | D22: P023 | E22: 1 | F22: 50000 | G22: 50000 | H22: DISC15 | I22: 7500 | J22: 15000 | K22: 57500 | L22: COD | M22: JNE | N22: Delivered | O22: 45809 | P22: Yes | Q22: 42500 | R22: Botol Minum Olahraga 1 Liter BPA Free | S22: Sports | T22: Active | U22: Deni Adi Irawan Nugroho | V22: Female | W22: Malang | X22: Gold
A23: ORD00126 | B23: 45737 | C23: CUST0007 | D23: P052 | E23: 3 | F23: 200000 | G23: 600000 | H23: NONE | I23: 0 | J23: 20000 | K23: 620000 | L23: E-Wallet | M23: J&T | N23: Delivered | O23: 45717 | P23: Yes | Q23: 600000 | R23: Eye Cream Anti Dark Circle | S23: Beauty | T23: GlowUp | U23: Irene Dwi Prasetyo | V23: Female | W23: Bandung | X23: Bronze
A24: ORD00230 | B24: 45813 | C24: CUST0007 | D24: P004 | E24: 2 | F24: 300000 | G24: 600000 | H24: NONE | I24: 0 | J24: 15000 | K24: 615000 | L24: E-Wallet | M24: AnterAja | N24: Cancelled | O24: 45809 | P24: No | Q24: 600000 | R24: Serum Wajah Brightening Vitamin C | S24: Beauty | T24: GlowUp | U24: Irene Dwi Prasetyo | V24: Female | W24: Bandung | X24: Bronze
A25: ORD00004 | B25: 45706 | C25: CUST0286 | D25: P016 | E25: 1 | F25: 150000 | G25: 150000 | H25: DISC10 | I25: 15000 | J25: 25000 | K25: 160000 | L25: Credit Card | M25: SiCepat | N25: Delivered | O25: 45689 | P25: Yes | Q25: 135000 | R25: Sunscreen SPF 50 PA+++ Light | S25: Beauty | T25: GlowUp | U25: Dara Irawan | V25: Male | W25: Solo | X25: Silver
A26: ORD00118 | B26: 45692 | C26: CUST0286 | D26: P052 | E26: 3 | F26: 200000 | G26: 600000 | H26: DISC10 | I26: 60000 | J26: 10000 | K26: 550000 | L26: COD | M26: JNE | N26: Delivered | O26: 45689 | P26: Yes | Q26: 540000 | R26: Eye Cream Anti Dark Circle | S26: Beauty | T26: GlowUp | U26: Dara Irawan | V26: Male | W26: Solo | X26: Silver
A27: ORD00205 | B27: 45825 | C27: CUST0286 | D27: P009 | E27: 1 | F27: 300000 | G27: 300000 | H27: NONE | I27: 0 | J27: 10000 | K27: 310000 | L27: E-Wallet | M27: SiCepat | N27: Delivered | O27: 45809 | P27: Yes | Q27: 300000 | R27: Bantal Leher Memory Foam | S27: Home | T27: Casa | U27: Dara Irawan | V27: Male | W27: Solo | X27: Silver
A28: ORD00091 | B28: 45776 | C28: CUST0008 | D28: P050 | E28: 2 | F28: 200000 | G28: 400000 | H28: NONE | I28: 0 | J28: 15000 | K28: 415000 | L28: Credit Card | M28: AnterAja | N28: Delivered | O28: 45748 | P28: Yes | Q28: 400000 | R28: Kaos Polo Classic Fit | S28: Fashion | T28: Modest | U28: Rani Handayani | V28: Male | W28: Solo | X28: Bronze
A29: ORD00241 | B29: 45742 | C29: CUST0008 | D29: P028 | E29: 2 | F29: 50000 | G29: 100000 | H29: NONE | I29: 0 | J29: 20000 | K29: 120000 | L29: E-Wallet | M29: SiCepat | N29: Delivered | O29: 45717 | P29: Yes | Q29: 100000 | R29: Lip Tint Matte Long Lasting | S29: Beauty | T29: GlowUp | U29: Rani Handayani | V29: Male | W29: Solo | X29: Bronze
A30: ORD00042 | B30: 45746 | C30: CUST0329 | D30: P004 | E30: 3 | F30: 300000 | G30: 900000 | H30: NONE | I30: 0 | J30: 25000 | K30: 925000 | L30: E-Wallet | M30: AnterAja | N30: Processing | O30: 45717 | P30: No | Q30: 900000 | R30: Serum Wajah Brightening Vitamin C | S30: Beauty | T30: GlowUp | U30: Amelia Bintang Susanto Lestari | V30: Male | W30: Solo | X30: Gold
A31: ORD00247 | B31: 45705 | C31: CUST0329 | D31: P008 | E31: 2 | F31: 150000 | G31: 300000 | H31: NEWUSER | I31: 30000 | J31: 20000 | K31: 290000 | L31: Credit Card | M31: JNE | N31: Delivered | O31: 45689 | P31: Yes | Q31: 270000 | R31: Kaos Polos Cotton Combed 30s | S31: Fashion | T31: Modest | U31: Amelia Bintang Susanto Lestari | V31: Male | W31: Solo | X31: Gold
A32: ORD00005 | B32: 45770 | C32: CUST0114 | D32: P030 | E32: 3 | F32: 100000 | G32: 300000 | H32: NEWUSER | I32: 30000 | J32: 20000 | K32: 290000 | L32: Bank Transfer | M32: AnterAja | N32: Shipped | O32: 45748 | P32: No | Q32: 270000 | R32: Buku Psikologi Manusia & Perilaku | S32: Books | T32: Insight | U32: Cahya Dwi Anggraini Iskandar | V32: Female | W32: Yogyakarta | X32: Bronze
A33: ORD00141 | B33: 45754 | C33: CUST0010 | D33: P050 | E33: 1 | F33: 200000 | G33: 200000 | H33: DISC10 | I33: 20000 | J33: 15000 | K33: 195000 | L33: Credit Card | M33: AnterAja | N33: Delivered | O33: 45748 | P33: Yes | Q33: 180000 | R33: Kaos Polo Classic Fit | S33: Fashion | T33: Modest | U33: Olivia Lestari | V33: Female | W33: Depok | X33: Bronze
... A121: ORD00022 | B121: 45766 | C121: CUST0201 | D121: P026 | E121: 1 | F121: 200000 | G121: 200000 | H121: NONE | I121: 0 | J121: 30000 | K121: 230000 | L121: Bank Transfer | M121: JNE | N121: Delivered | O121: 45748 | P121: Yes | Q121: 200000 | R121: Hijab Segiempat Premium Silk | S121: Fashion | T121: Modest | U121: Doni Kirana Permata | V121: Male | W121: Tangerang | X121: Silver
A122: ORD00125 | B122: 45706 | C122: CUST0042 | D122: P038 | E122: 1 | F122: 35000 | G122: 35000 | I122: 3500 | J122: 20000 | K122: 51500 | L122: Credit Card | M122: J&T | N122: Delivered | O122: 45689 | P122: Yes | Q122: 31500 | R122: Sweater Rajut Outer Premium | S122: Fashion | T122: Modest | U122: Dania Pratama | V122: Female | W122: Yogyakarta | X122: Bronze
A123: ORD00023 | B123: 45828 | C123: CUST0104 | D123: P042 | E123: 1 | F123: 300000 | G123: 300000 | H123: NONE | I123: 0 | J123: 20000 | K123: 320000 | L123: COD | M123: JNE | N123: Delivered | O123: 45809 | P123: Yes | Q123: 300000 | R123: Buku Pemrograman Python & Data Analytics | S123: Books | T123: Insight | U123: Sari Yuliani | V123: Female | W123: Solo | X123: Bronze
A124: ORD00157 | B124: 45789 | C124: CUST0104 | D124: P035 | E124: 1 | F124: 200000 | G124: 200000 | H124: DISC15 | I124: 30000 | J124: 20000 | K124: 190000 | L124: E-Wallet | M124: JNE | N124: Delivered | O124: 45778 | P124: Yes | Q124: 170000 | R124: Hand Grip Adjustable Trainer | S124: Sports | T124: Active | U124: Sari Yuliani | V124: Female | W124: Solo | X124: Bronze
A125: ORD00281 | B125: 45747 | C125: CUST0104 | D125: P009 | E125: 4 | F125: 300000 | G125: 1200000 | H125: DISC10 | I125: 120000 | J125: 25000 | K125: 1105000 | L125: COD | M125: J&T | N125: Shipped | O125: 45717 | P125: No | Q125: 1080000 | R125: Bantal Leher Memory Foam | S125: Home | T125: Casa | U125: Sari Yuliani | V125: Female | W125: Solo | X125: Bronze
A126: ORD00101 | B126: 45672 | C126: CUST0043 | D126: P048 | E126: 4 | F126: 300000 | G126: 1200000 | H126: DISC10 | I126: 120000 | J126: 30000 | K126: 1110000 | L126: Credit Card | M126: SiCepat | N126: Processing | O126: 45658 | P126: No | Q126: 1080000 | R126: Buku Desain Grafis & Kreativitas | S126: Books | T126: Insight | U126: Nanda Kirana Pratama | V126: Female | W126: Solo | X126: Bronze
A127: ORD00174 | B127: 45727 | C127: CUST0044 | D127: P009 | E127: 2 | F127: 300000 | G127: 600000 | H127: FLASHSALE | I127: 120000 | J127: 10000 | K127: 490000 | L127: Bank Transfer | M127: J&T | N127: Processing | O127: 45717 | P127: No | Q127: 480000 | R127: Bantal Leher Memory Foam | S127: Home | T127: Casa | U127: Mia Santoso | V127: Female | W127: Surabaya | X127: Gold
A128: ORD00047 | B128: 45737 | C128: CUST0168 | D128: P028 | E128: 1 | F128: 50000 | G128: 50000 | H128: NEWUSER | I128: 5000 | J128: 10000 | K128: 55000 | L128: Bank Transfer | M128: JNE | N128: Delivered | O128: 45717 | P128: Yes | Q128: 45000 | R128: Lip Tint Matte Long Lasting | S128: Beauty | T128: GlowUp | U128: Ghani Ramadhan | V128: Female | W128: Yogyakarta | X128: Silver
A129: ORD00319 | B129: 45834 | C129: CUST0168 | D129: P019 | E129: 2 | F129: 500000 | G129: 1000000 | H129: NONE | I129: 0 | J129: 20000 | K129: 1020000 | L129: Credit Card | M129: J&T | N129: Delivered | O129: 45809 | P129: Yes | Q129: 1000000 | R129: Powerbank 10000mAh Ultra Slim | S129: Electronics | T129: Atech | U129: Ghani Ramadhan | V129: Female | W129: Yogyakarta | X129: Silver
A130: ORD00233 | B130: 45732 | C130: CUST0045 | D130: P004 | E130: 1 | F130: 300000 | G130: 300000 | H130: NONE | I130: 0 | J130: 20000 | K130: 320000 | L130: Bank Transfer | M130: AnterAja | N130: Delivered | O130: 45717 | P130: Yes | Q130: 300000 | R130: Serum Wajah Brightening Vitamin C | S130: Beauty | T130: GlowUp | U130: Danu Pangestu | V130: Female | W130: Depok | X130: Silver
A131: ORD00030 | B131: 45765 | C131: CUST0188 | D131: P045 | E131: 1 | F131: 100000 | G131: 100000 | H131: DISC15 | I131: 15000 | J131: 25000 | K131: 110000 | L131: E-Wallet | M131: J&T | N131: Cancelled | O131: 45748 | P131: No | Q131: 85000 | R131: Diffuser Aromaterapi Ultrasonik | S131: Home | T131: Casa | U131: Arman Suryani | V131: Male | W131: Jakarta | X131: Bronze
A132: ORD00201 | B132: 45777 | C132: CUST0046 | D132: P038 | E132: 3 | F132: 35000 | G132: 105000 | H132: NONE | I132: 0 | J132: 20000 | K132: 125000 | L132: E-Wallet | M132: SiCepat | N132: Processing | O132: 45748 | P132: No | Q132: 105000 | R132: Sweater Rajut Outer Premium | S132: Fashion | T132: Modest | U132: Nanda Ayu Salim | V132: Female | W132: Yogyakarta | X132: Gold
A133: ORD00333 | B133: 45807 | C133: CUST0048 | D133: P021 | E133: 1 | F133: 200000 | G133: 200000 | H133: DISC15 | I133: 30000 | J133: 25000 | K133: 195000 | L133: Credit Card | M133: J&T | N133: Shipped | O133: 45778 | P133: No | Q133: 170000 | R133: Set Pisau Dapur Stainless Steel | S133: Home | T133: Casa | U133: Julia Adi Wulandari | V133: Female | W133: Jakarta | X133: Silver
...

Sheet sales_performance
B1: Start Date | C1: =MIN(clean[order_date]) -> 45658
B2: End Date | C2: =MAX(clean[order_date]) -> 45838
B5: Monthly Report | K5: Order Status
B7: Row Labels | C7: Count of order_id | D7: Sum of quantity | E7: Sum of gross_sales | F7: Sum of total_amount | G7: Sum of net_sales | H7: Sum of revenue | I7: revenue_growth | K7: status | L7: Count of order_id | M7: status %
B8: Jan | C8: 216 | D8: 421 | E8: 83430000 | F8: 81608500 | G8: 77378500 | H8: 47920500 | I8: 0 | K8: Cancelled | L8: 79 | M8: =GETPIVOTDATA("order_id",$K$7,"order_status",K8)/GETPIVOTDATA("Count of order_id",$B$7) -> 0.065833333
B9: Feb | C9: 171 | D9: 347 | E9: 69485000 | F9: 68041750 | G9: 64571750 | H9: 42315750 | I9: =(GETPIVOTDATA("Sum of revenue",$B$7,"Months (month)",B9)-GETPIVOTDATA("Sum of revenue",$B$7,"Months (month)",B8))/GETPIVOTDATA("Sum of revenue",$B$7,"Months (month)",B8) -> -0.11695934 | K9: Delivered | L9: 819 | M9: =GETPIVOTDATA("order_id",$K$7,"order_status",K9)/GETPIVOTDATA("Count of order_id",$B$7) -> 0.6825
B10: Mar | C10: 203 | D10: 394 | E10: 89540000 | F10: 87402500 | G10: 83297500 | H10: 59330250 | I10: =(GETPIVOTDATA("Sum of revenue",$B$7,"Months (month)",B10)-GETPIVOTDATA("Sum of revenue",$B$7,"Months (month)",B9))/GETPIVOTDATA("Sum of revenue",$B$7,"Months (month)",B9) -> 0.40208433 | K10: Processing | L10: 109 | M10: =GETPIVOTDATA("order_id",$K$7,"order_status",K10)/GETPIVOTDATA("Count of order_id",$B$7) -> 0.090833333
B11: Apr | C11: 210 | D11: 430 | E11: 81245000 | F11: 79834750 | G11: 75629750 | H11: 56147000 | I11: =(GETPIVOTDATA("Sum of revenue",$B$7,"Months (month)",B11)-GETPIVOTDATA("Sum of revenue",$B$7,"Months (month)",B10))/GETPIVOTDATA("Sum of revenue",$B$7,"Months (month)",B10) -> -0.053653069 | K11: Returned | L11: 49 | M11: =GETPIVOTDATA("order_id",$K$7,"order_status",K11)/GETPIVOTDATA("Count of order_id",$B$7) -> 0.040833333
B12: May | C12: 213 | D12: 411 | E12: 82270000 | F12: 80677750 | G12: 76462750 | H12: 53123000 | I12: =(GETPIVOTDATA("Sum of revenue",$B$7,"Months (month)",B12)-GETPIVOTDATA("Sum of revenue",$B$7,"Months (month)",B11))/GETPIVOTDATA("Sum of revenue",$B$7,"Months (month)",B11) -> -0.053858621 | K12: Shipped | L12: 144 | M12: =GETPIVOTDATA("order_id",$K$7,"order_status",K12)/GETPIVOTDATA("Count of order_id",$B$7) -> 0.12
B13: Jun | C13: 187 | D13: 365 | E13: 70965000 | F13: 69804500 | G13: 66124500 | H13: 40399750 | I13: =(GETPIVOTDATA("Sum of revenue",$B$7,"Months (month)",B13)-GETPIVOTDATA("Sum of revenue",$B$7,"Months (month)",B12))/GETPIVOTDATA("Sum of revenue",$B$7,"Months (month)",B12) -> -0.23950549 | K13: Grand Total | L13: 1200
B14: Grand Total | C14: 1200 | D14: 2368 | E14: 476935000 | F14: 467369750 | G14: 443464750 | H14: 299236250
K15: Processing + Shipped | L15: =GETPIVOTDATA("order_id",$K$7,"order_status","Processing")+GETPIVOTDATA("order_id",$K$7,"order_status","Shipped") -> 253 | M15: =L15/GETPIVOTDATA("order_id",$K$7) -> 0.21083333
B16: Revenue by City | G16: KPI | K16: Cancelled + Returned | L16: =GETPIVOTDATA("order_id",$K$7,"order_status","Cancelled")+GETPIVOTDATA("order_id",$K$7,"order_status","Returned") -> 128 | M16: =L16/GETPIVOTDATA("order_id",$K$7) -> 0.10666667
L17: =L15+L16 -> 381 | M17: =L17/GETPIVOTDATA("order_id",$K$7) -> 0.3175
B18: Row Labels | C18: Count of order_id | D18: Sum of revenue | E18: revenue/order | G18: Total Orders | H18: =GETPIVOTDATA("Count of order_id",$B$7) -> 1200
B19: Malang | C19: 127 | D19: 42270250 | E19: =GETPIVOTDATA("Sum of revenue",$B$18,"city",B19)/GETPIVOTDATA("Count of order_id",$B$18,"city",B19) -> 332836.61 | G19: Total Quantity | H19: =GETPIVOTDATA("Sum of quantity",$B$7) -> 2368
B20: Tangerang | C20: 159 | D20: 38708000 | E20: =GETPIVOTDATA("Sum of revenue",$B$18,"city",B20)/GETPIVOTDATA("Count of order_id",$B$18,"city",B20) -> 243446.54 | G20: Gross Sales | H20: =GETPIVOTDATA("Sum of gross_sales",$B$7) -> 476935000 | J20: Insights
B21: Yogyakarta | C21: 147 | D21: 38575000 | E21: =GETPIVOTDATA("Sum of revenue",$B$18,"city",B21)/GETPIVOTDATA("Count of order_id",$B$18,"city",B21) -> 262414.97 | G21: Total Amount | H21: =GETPIVOTDATA("Sum of total_amount",$B$7) -> 467369750 | J21: 1. Revenue declined significantly in June, falling 23.95% from May to Rp40.40M, making June the lowest-revenue month in the period. 2. March recorded the highest monthly revenue at Rp59.33M, supported by a relatively high revenue per order. 3. Delivered orders account for only 68.25% of total orders, while 31.75% remain non-delivered, indicating an opportunity to improve order fulfillment. 4. Cancelled and returned orders represent 10.67% of total orders, which may indicate potential fulfillment or customer-experience issues requiring further investigation. 5. Malang generated the highest city revenue at Rp42.27M despite having fewer orders than Jakarta, indicating a higher revenue per order in Malang.
B22: Semarang | C22: 120 | D22: 38030500 | E22: =GETPIVOTDATA("Sum of revenue",$B$18,"city",B22)/GETPIVOTDATA("Count of order_id",$B$18,"city",B22) -> 316920.83 | G22: Net Sales | H22: =GETPIVOTDATA("Sum of net_sales",$B$7) -> 443464750
B23: Jakarta | C23: 161 | D23: 32218750 | E23: =GETPIVOTDATA("Sum of revenue",$B$18,"city",B23)/GETPIVOTDATA("Count of order_id",$B$18,"city",B23) -> 200116.46 | G23: Revenue | H23: =GETPIVOTDATA("Sum of revenue",$B$7) -> 299236250
B24: Surabaya | C24: 141 | D24: 25736750 | E24: =GETPIVOTDATA("Sum of revenue",$B$18,"city",B24)/GETPIVOTDATA("Count of order_id",$B$18,"city",B24) -> 182530.14 | G24: AOV | H24: =GETPIVOTDATA("Sum of revenue",$B$7)/GETPIVOTDATA("Count of order_id",$B$7) -> 249363.54
B25: Depok | C25: 96 | D25: 23666750 | E25: =GETPIVOTDATA("Sum of revenue",$B$18,"city",B25)/GETPIVOTDATA("Count of order_id",$B$18,"city",B25) -> 246528.65 | G25: Delivered Rate | H25: =GETPIVOTDATA("order_id",$K$7,"order_status",K9)/GETPIVOTDATA("Count of order_id",$B$7) -> 0.6825
B26: Bandung | C26: 80 | D26: 22599000 | E26: =GETPIVOTDATA("Sum of revenue",$B$18,"city",B26)/GETPIVOTDATA("Count of order_id",$B$18,"city",B26) -> 282487.5
B27: Solo | C27: 93 | D27: 20798000 | E27: =GETPIVOTDATA("Sum of revenue",$B$18,"city",B27)/GETPIVOTDATA("Count of order_id",$B$18,"city",B27) -> 223634.41
B28: Bekasi | C28: 76 | D28: 16633250 | E28: =GETPIVOTDATA("Sum of revenue",$B$18,"city",B28)/GETPIVOTDATA("Count of order_id",$B$18,"city",B28) -> 218858.55
B29: Grand Total | C29: 1200 | D29: 299236250

Sheet products_performance
B1: Start Date | C1: =MIN(clean[order_date]) -> 45658
B2: End Date | C2: =MAX(clean[order_date]) -> 45838
B4: Total Order | C4: =GETPIVOTDATA("Count of order_id",sales_performance!$B$7) -> 1200
B5: Top Product by Total Order | F5: Top Product by Total Quantity | J5: Top Product by Total Revenue
B7: Row Labels | C7: Count of order_id | D7: Product Contribution | F7: Row Labels | G7: Sum of quantity | H7: Product Contribution | J7: Row Labels | K7: Sum of revenue | L7: Product Contribution
B8: Keyboard Mechanical RGB Light | C8: 31 | D8: =GETPIVOTDATA("order_id",B7,"product_name",B8)/GETPIVOTDATA("Count of order_id",sales_performance!$B$7) -> 0.025833333 | F8: Keyboard Mechanical RGB Light | G8: 63 | H8: =GETPIVOTDATA("quantity",F7,"product_name",F8)/GETPIVOTDATA("Sum of quantity",sales_performance!$B$7) -> 0.02660473 | J8: Lampu Tidur LED Smart Touch | K8: 16675000 | L8: =GETPIVOTDATA("revenue",J7,"product_name",J8)/GETPIVOTDATA("Sum of revenue",sales_performance!$B$7) -> 0.0557252
B9: Kaos Polos Cotton Combed 30s | C9: 30 | D9: =GETPIVOTDATA("order_id",B8,"product_name",B9)/GETPIVOTDATA("Count of order_id",sales_performance!$B$7) -> 0.025 | F9: Serum Wajah Brightening Vitamin C | G9: 56 | H9: =GETPIVOTDATA("quantity",F8,"product_name",F9)/GETPIVOTDATA("Sum of quantity",sales_performance!$B$7) -> 0.023648649 | J9: Buku Keuangan & Manajemen Investasi | K9: 16450000 | L9: =GETPIVOTDATA("revenue",J8,"product_name",J9)/GETPIVOTDATA("Sum of revenue",sales_performance!$B$7) -> 0.054973286
B10: Kabel Data Fast Charge USB-C | C10: 27 | D10: =GETPIVOTDATA("order_id",B9,"product_name",B10)/GETPIVOTDATA("Count of order_id",sales_performance!$B$7) -> 0.0225 | F10: Buku Keuangan & Manajemen Investasi | G10: 56 | H10: =GETPIVOTDATA("quantity",F9,"product_name",F10)/GETPIVOTDATA("Sum of quantity",sales_performance!$B$7) -> 0.023648649 | J10: Bola Basket Indoor Outdoor | K10: 14850000 | L10: =GETPIVOTDATA("revenue",J9,"product_name",J10)/GETPIVOTDATA("Sum of revenue",sales_performance!$B$7) -> 0.04962634
B11: Masker Wajah Sheet Mask Hydra | C11: 27 | D11: =GETPIVOTDATA("order_id",B10,"product_name",B11)/GETPIVOTDATA("Count of order_id",sales_performance!$B$7) -> 0.0225 | F11: Busa Foam Roller Massage | G11: 56 | H11: =GETPIVOTDATA("quantity",F10,"product_name",F11)/GETPIVOTDATA("Sum of quantity",sales_performance!$B$7) -> 0.023648649 | J11: Buku Novel Fiksi Inspiratif Terbaik | K11: 13850000 | L11: =GETPIVOTDATA("revenue",J10,"product_name",J11)/GETPIVOTDATA("Sum of revenue",sales_performance!$B$7) -> 0.046284499
B12: Buku Novel Fiksi Inspiratif Terbaik | C12: 27 | D12: =GETPIVOTDATA("order_id",B11,"product_name",B12)/GETPIVOTDATA("Count of order_id",sales_performance!$B$7) -> 0.0225 | F12: Sprei Katun Jepang Soft | G12: 54 | H12: =GETPIVOTDATA("quantity",F11,"product_name",F12)/GETPIVOTDATA("Sum of quantity",sales_performance!$B$7) -> 0.022804054 | J12: Powerbank 10000mAh Ultra Slim | K12: 12050000 | L12: =GETPIVOTDATA("revenue",J11,"product_name",J12)/GETPIVOTDATA("Sum of revenue",sales_performance!$B$7) -> 0.040269185
B13: Gamis Syar'i Elegant Edition | C13: 26 | D13: =GETPIVOTDATA("order_id",B12,"product_name",B13)/GETPIVOTDATA("Count of order_id",sales_performance!$B$7) -> 0.021666667 | F13: Buku Desain Grafis & Kreativitas | G13: 54 | H13: =GETPIVOTDATA("quantity",F12,"product_name",F13)/GETPIVOTDATA("Sum of quantity",sales_performance!$B$7) -> 0.022804054 | J13: Resistance Band Loop Set | K13: 11700000 | L13: =GETPIVOTDATA("revenue",J12,"product_name",J13)/GETPIVOTDATA("Sum of revenue",sales_performance!$B$7) -> 0.039099541
B14: Serum Wajah Brightening Vitamin C | C14: 25 | D14: =GETPIVOTDATA("order_id",B13,"product_name",B14)/GETPIVOTDATA("Count of order_id",sales_performance!$B$7) -> 0.020833333 | F14: Tali Skipping Adjustable Speed | G14: 52 | H14: =GETPIVOTDATA("quantity",F13,"product_name",F14)/GETPIVOTDATA("Sum of quantity",sales_performance!$B$7) -> 0.021959459 | J14: Keyboard Mechanical RGB Light | K14: 11670000 | L14: =GETPIVOTDATA("revenue",J13,"product_name",J14)/GETPIVOTDATA("Sum of revenue",sales_performance!$B$7) -> 0.038999286
B15: Jaket Hoodie Oversize Soft | C15: 25 | D15: =GETPIVOTDATA("order_id",B14,"product_name",B15)/GETPIVOTDATA("Count of order_id",sales_performance!$B$7) -> 0.020833333 | F15: Kaos Polos Cotton Combed 30s | G15: 52 | H15: =GETPIVOTDATA("quantity",F14,"product_name",F15)/GETPIVOTDATA("Sum of quantity",sales_performance!$B$7) -> 0.021959459 | J15: Celana Jeans Stretch Slim | K15: 11625000 | L15: =GETPIVOTDATA("revenue",J14,"product_name",J15)/GETPIVOTDATA("Sum of revenue",sales_performance!$B$7) -> 0.038848903
B16: Tali Skipping Adjustable Speed | C16: 25 | D16: =GETPIVOTDATA("order_id",B15,"product_name",B16)/GETPIVOTDATA("Count of order_id",sales_performance!$B$7) -> 0.020833333 | F16: Kabel Data Fast Charge USB-C | G16: 51 | H16: =GETPIVOTDATA("quantity",F15,"product_name",F16)/GETPIVOTDATA("Sum of quantity",sales_performance!$B$7) -> 0.021537162 | J16: Cangkir Keramik Aesthetic Set | K16: 10975000 | L16: =GETPIVOTDATA("revenue",J15,"product_name",J16)/GETPIVOTDATA("Sum of revenue",sales_performance!$B$7) -> 0.036676706
B17: Buku Keuangan & Manajemen Investasi | C17: 25 | D17: =GETPIVOTDATA("order_id",B16,"product_name",B17)/GETPIVOTDATA("Count of order_id",sales_performance!$B$7) -> 0.020833333 | F17: Masker Wajah Sheet Mask Hydra | G17: 51 | H17: =GETPIVOTDATA("quantity",F16,"product_name",F17)/GETPIVOTDATA("Sum of quantity",sales_performance!$B$7) -> 0.021537162 | J17: Buku Desain Grafis & Kreativitas | K17: 10815000 | L17: =GETPIVOTDATA("revenue",J16,"product_name",J17)/GETPIVOTDATA("Sum of revenue",sales_performance!$B$7) -> 0.036142012
B18: Lampu Tidur LED Smart Touch | C18: 25 | D18: =GETPIVOTDATA("order_id",B17,"product_name",B18)/GETPIVOTDATA("Count of order_id",sales_performance!$B$7) -> 0.020833333 | F18: Grand Total | G18: 545 | J18: Grand Total | K18: 130660000 | L18: =GETPIVOTDATA("revenue",$J$7)/GETPIVOTDATA("Sum of revenue",sales_performance!$B$7) -> 0.43664496
B19: Grand Total | C19: 293
B21: Category Report | G21: Brand Report
B23: Row Labels | C23: Count of order_id | D23: Sum of quantity | E23: Sum of revenue | G23: Row Labels | H23: Count of order_id | I23: Sum of quantity | J23: Sum of revenue | L23: Insights
B24: Books | C24: 209 | D24: 416 | E24: 80540000 | G24: Active | H24: 200 | I24: 428 | J24: 45548750 | L24: 1. The top 10 products generated Rp130.66M, contributing approximately 43.66% of total revenue. 2. Lampu Tidur LED Smart Touch is the highest-revenue product, generating Rp16.68M or 5.57% of total revenue. 3. Books is the strongest revenue category, generating Rp80.54M or approximately 26.92% of total revenue. 4. Sports recorded the highest quantity at 428 units, but generated only Rp45.55M in revenue, suggesting that high sales volume does not necessarily translate into the highest revenue. 5. Insight is the highest-revenue brand, generating Rp80.54M or approximately 26.92% of total revenue.
B25: Home | C25: 198 | D25: 386 | E25: 59276250 | G25: Atech | H25: 199 | I25: 386 | J25: 52222500
B26: Electronics | C26: 199 | D26: 386 | E26: 52222500 | G26: Casa | H26: 198 | I26: 386 | J26: 59276250
B27: Sports | C27: 200 | D27: 428 | E27: 45548750 | G27: GlowUp | H27: 199 | I27: 389 | J27: 29023000
B28: Fashion | C28: 195 | D28: 363 | E28: 32625750 | G28: Insight | H28: 209 | I28: 416 | J28: 80540000
B29: Beauty | C29: 199 | D29: 389 | E29: 29023000 | G29: Modest | H29: 195 | I29: 363 | J29: 32625750
B30: Grand Total | C30: 1200 | D30: 2368 | E30: 299236250 | G30: Grand Total | H30: 1200 | I30: 2368 | J30: 299236250

Sheet customers_performance
B1: Start Date | C1: =MIN(clean[order_date]) -> 45658
B2: End Date | C2: =MAX(clean[order_date]) -> 45838
B4: Total Customers | C4: =COUNTA(_xlfn.UNIQUE(customers[customer_id])) -> 350 | E4: Total Customers with Order | F4: =COUNTA(_xlfn.UNIQUE(clean[customer_id])) -> 340 | H4: Total Customers without Order | I4: {=SUM(--(COUNTIF(clean[customer_name],customers[customer_name])=0))} -> 10
B5: Top 10 Customer by Revenue
B7: Row Labels | C7: Sum of revenue | D7: Count of order_id | E7: Sum of quantity | H7: Row Labels | I7: Count of order_id | J7: Sum of quantity | K7: Sum of revenue
B8: Dewi Utami | C8: 4496500 | D8: 7 | E8: 14 | H8: Female | I8: 621 | J8: 1203 | K8: 160825750
B9: Raka Naufal Kusuma | C9: 3355000 | D9: 6 | E9: 14 | H9: Male | I9: 579 | J9: 1165 | K9: 138410500
B10: Doni Anjani Suryani | C10: 3270000 | D10: 6 | E10: 15 | H10: Grand Total | I10: 1200 | J10: 2368 | K10: 299236250
B11: Aulia Suryanto | C11: 3262500 | D11: 6 | E11: 11
B12: Dimas Nur Permadi | C12: 3080000 | D12: 3 | E12: 9
B13: Fikri Utami | C13: 3040000 | D13: 5 | E13: 13
B14: Wahyu Handayani | C14: 2950000 | D14: 7 | E14: 17 | H14: Row Labels | I14: Count of order_id | J14: Sum of quantity | K14: Sum of revenue
B15: Taufik Rizal Susanto | C15: 2940000 | D15: 6 | E15: 13 | H15: Bronze | I15: 671 | J15: 1322 | K15: 156556750
B16: Alya Anjani Hidayat | C16: 2940000 | D16: 5 | E16: 9 | H16: Gold | I16: 190 | J16: 365 | K16: 50753000
B17: Aditya Naufal Hidayat | C17: 2840000 | D17: 7 | E17: 19 | H17: Silver | I17: 339 | J17: 681 | K17: 91926500
B18: Grand Total | C18: 32174000 | D18: 58 | E18: 134 | H18: Grand Total | I18: 1200 | J18: 2368 | K18: 299236250
B20: Repeat Customer | E20: New Customers | H20: Customers without Order
B22: customer_name | C22: total_orders_customer | E22: customer_name | F22: total_orders_customer | H22: customer_name | I22: total_orders_customer | K22: status | L22: total_customers | M22: customers_contribution
B23: {=_xlfn.UNIQUE(_xlfn._xlws.FILTER(clean[customer_name],COUNTIF(clean[customer_name],clean[customer_name])>1))} -> Rafi Pangestu | C23: {=COUNTIF(clean[customer_name],_xlfn.ANCHORARRAY(B23))} -> 2 | E23: {=_xlfn.UNIQUE(_xlfn._xlws.FILTER(clean[customer_name],COUNTIF(clean[customer_name],clean[customer_name])=1))} -> Naufal Bintang Anggraini Wibowo | F23: {=COUNTIF(clean[customer_name],_xlfn.ANCHORARRAY(E23))} -> 1 | H23: {=_xlfn._xlws.FILTER(customers[customer_name],COUNTIF(clean[customer_name],customers[customer_name])=0)} -> Dinda Utami | I23: 0 | K23: repeat_customers | L23: =COUNTA(_xlfn.ANCHORARRAY(B23)) -> 300 | M23: =L23/C4 -> 0.85714286
B24: Laura Dian Permadi | C24: 6 | E24: Ganesha Ananda | F24: 1 | H24: Sofyan Abdullah | I24: 0 | K24: new_customer | L24: =COUNTA(_xlfn.ANCHORARRAY(E23)) -> 40 | M24: =L24/C4 -> 0.11428571
B25: Rosa Dwi Laksono Wulandari | C25: 6 | E25: Laura Anjani Prasetyo | F25: 1 | H25: Sofyan Dwi Siregar | I25: 0 | K25: without_order | L25: =COUNTA(_xlfn.ANCHORARRAY(H23)) -> 10 | M25: =L25/C4 -> 0.028571429
B26: Mia Santoso | C26: 6 | E26: Nisa Siregar | F26: 1 | H26: Dinda Salim | I26: 0
B27: Fikri Herlambang | C27: 3 | E27: Fauzan Utami | F27: 1 | H27: Surya Setyawan | I27: 0
B28: Oscar Bintang Maulana | C28: 5 | E28: Aisyah Lestari | F28: 1 | H28: Nadia Sari Suryanto | I28: 0
B29: Sheila Bayu Kusnadi | C29: 3 | E29: Andika Kirana Wardana | F29: 1 | H29: Nadia Ramadhan | I29: 0
B30: Elang Hidayat | C30: 3 | E30: Ganesha Putri | F30: 1 | H30: Nabila Galang Wardana | I30: 0
B31: Indra Kurnia | C31: 5 | E31: Elsa Firmansyah | F31: 1 | H31: Salsa Fajar Maulana Putri | I31: 0
B32: Miko Anjani Wulandari | C32: 3 | E32: Yudha Ayu Putri | F32: 1 | H32: Julia Irawan | I32: 0
B33: Aulia Citra Kusuma Cahyani | C33: 5 | E33: Hanif Ningsih | F33: 1
B34: Aditya Anggraini | C34: 4 | E34: Dania Bintang Suryani | F34: 1
B35: Deni Adi Irawan Nugroho | C35: 4 | E35: Rani Yuliani | F35: 1
B36: Nisa Bayu Kusnadi | C36: 6 | E36: Irfan Fajar Prasetyo | F36: 1 | H36: Inaights
B37: Aditya Naufal Hidayat | C37: 7 | E37: Laura Adi Saputra | F37: 1 | H37: 1. Customer retention is strong, with 300 of 340 customers with orders classified as repeat customers, resulting in an 88.24% repeat customer rate. 2. Only 10 customers have not placed an order, representing 2.86% of the total customer base and providing a small but identifiable target for first-purchase campaigns. 3. The top 10 customers generated Rp32.17M, contributing approximately 10.76% of total revenue, indicating that revenue is not heavily concentrated among a small number of customers. 4. Female customers generated higher revenue than male customers (Rp160.83M vs. Rp138.41M), with female customers also having a higher revenue per order. 5. Bronze customers generated the highest total revenue at Rp156.56M, while Silver and Gold customers recorded higher revenue per order, indicating an opportunity to increase customer migration toward higher membership tiers.
B38: Fadli Rahman | C38: 3 | E38: Nadia Permata | F38: 1
B39: Yusuf Fauzi | C39: 3 | E39: Putri Rizal Saputra | F39: 1
B40: Rizky Hidayat | C40: 5 | E40: Daffa Rizal Suryanto Wardana | F40: 1
B41: Arman Ayu Maulana | C41: 5 | E41: Hafiz Citra Iskandar | F41: 1
B42: Raka Naufal Kusuma | C42: 6 | E42: Irene Adi Nugroho Hidayat | F42: 1
B43: Ratih Putri Kusnadi | C43: 3 | E43: Rafi Utami | F43: 1
B44: Febri Kusuma | C44: 6 | E44: Daffa Dian Irawan Permadi | F44: 1
...

Sheet orders
A1: order_id | B1: order_date | C1: customer_id | D1: product_id | E1: quantity | F1: unit_price | G1: gross_sales | H1: promo_code | I1: discount | J1: shipping_cost | K1: total_amount | L1: payment_method | M1: courier | N1: order_status | O1: month | P1: is_delivered | Q1: net_sales
A2: ORD00001 | B2: 45745 | C2: CUST0161 | D2: P049 | E2: 2 | F2: 200000 | G2: 400000 | H2: NONE | I2: 0 | J2: 10000 | K2: 410000 | L2: Credit Card | M2: AnterAja | N2: Delivered | O2: 2025-03 | P2: Yes | Q2: 400000
A3: ORD00002 | B3: 45738 | C3: CUST0084 | D3: P041 | E3: 1 | F3: 75000 | G3: 75000 | H3: FLASHSALE | I3: 15000 | J3: 10000 | K3: 70000 | L3: COD | M3: SiCepat | N3: Delivered | O3: 2025-03 | P3: Yes | Q3: 60000
A4: ORD00003 | B4: 45728 | C4: CUST0257 | D4: P032 | E4: 2 | F4: 35000 | G4: 70000 | H4: NEWUSER | I4: 7000 | J4: 30000 | K4: 93000 | L4: E-Wallet | M4: AnterAja | N4: Delivered | O4: 2025-03 | P4: Yes | Q4: 63000
A5: ORD00004 | B5: 45706 | C5: CUST0286 | D5: P016 | E5: 1 | F5: 150000 | G5: 150000 | H5: DISC10 | I5: 15000 | J5: 25000 | K5: 160000 | L5: Credit Card | M5: SiCepat | N5: Delivered | O5: 2025-02 | P5: Yes | Q5: 135000
A6: ORD00005 | B6: 45770 | C6: CUST0114 | D6: P030 | E6: 3 | F6: 100000 | G6: 300000 | H6: NEWUSER | I6: 30000 | J6: 20000 | K6: 290000 | L6: Bank Transfer | M6: AnterAja | N6: Shipped | O6: 2025-04 | P6: No | Q6: 270000
A7: ORD00006 | B7: 45689 | C7: CUST0266 | D7: P010 | E7: 1 | F7: 50000 | G7: 50000 | H7: FLASHSALE | I7: 10000 | J7: 15000 | K7: 55000 | L7: E-Wallet | M7: SiCepat | N7: Delivered | O7: 2025-02 | P7: Yes | Q7: 40000
A8: ORD00007 | B8: 45792 | C8: CUST0349 | D8: P008 | E8: 1 | F8: 150000 | G8: 150000 | H8: DISC15 | I8: 22500 | J8: 30000 | K8: 157500 | L8: E-Wallet | M8: SiCepat | N8: Delivered | O8: 2025-05 | P8: Yes | Q8: 127500
A9: ORD00008 | B9: 45729 | C9: CUST0054 | D9: P057 | E9: 4 | F9: 500000 | G9: 2000000 | H9: NONE | I9: 0 | J9: 15000 | K9: 2015000 | L9: COD | M9: AnterAja | N9: Delivered | O9: 2025-03 | P9: Yes | Q9: 2000000
A10: ORD00009 | B10: 45692 | C10: CUST0096 | D10: P024 | E10: 3 | F10: 500000 | G10: 1500000 | H10: NONE | I10: 0 | J10: 30000 | K10: 1530000 | L10: COD | M10: AnterAja | N10: Delivered | O10: 2025-02 | P10: Yes | Q10: 1500000
A11: ORD00010 | B11: 45799 | C11: CUST0223 | D11: P055 | E11: 1 | F11: 300000 | G11: 300000 | H11: NEWUSER | I11: 30000 | J11: 30000 | K11: 300000 | L11: Bank Transfer | M11: SiCepat | N11: Delivered | O11: 2025-05 | P11: Yes | Q11: 270000
A12: ORD00011 | B12: 45804 | C12: CUST0036 | D12: P029 | E12: 2 | F12: 500000 | G12: 1000000 | H12: NONE | I12: 0 | J12: 15000 | K12: 1015000 | L12: COD | M12: JNE | N12: Shipped | O12: 2025-05 | P12: No | Q12: 1000000
A13: ORD00012 | B13: 45787 | C13: CUST0195 | D13: P023 | E13: 4 | F13: 50000 | G13: 200000 | H13: DISC15 | I13: 30000 | J13: 10000 | K13: 180000 | L13: Credit Card | M13: J&T | N13: Delivered | O13: 2025-05 | P13: Yes | Q13: 170000
... A125: ORD00124 | B125: 45712 | C125: CUST0262 | D125: P035 | E125: 3 | F125: 200000 | G125: 600000 | H125: NONE | I125: 0 | J125: 25000 | K125: 625000 | L125: COD | M125: JNE | N125: Delivered | O125: 2025-02 | P125: Yes | Q125: 600000
A126: ORD00125 | B126: 45706 | C126: CUST0042 | D126: P038 | E126: 1 | F126: 35000 | G126: 35000 | I126: 3500 | J126: 20000 | K126: 51500 | L126: Credit Card | M126: J&T | N126: Delivered | O126: 2025-02 | P126: Yes | Q126: 31500
A127: ORD00126 | B127: 45737 | C127: CUST0007 | D127: P052 | E127: 3 | F127: 200000 | G127: 600000 | H127: NONE | I127: 0 | J127: 20000 | K127: 620000 | L127: E-Wallet | M127: J&T | N127: Delivered | O127: 2025-03 | P127: Yes | Q127: 600000
A128: ORD00127 | B128: 45677 | C128: CUST0256 | D128: P010 | E128: 1 | F128: 50000 | G128: 50000 | H128: FLASHSALE | I128: 10000 | J128: 10000 | K128: 50000 | L128: E-Wallet | M128: JNE | N128: Delivered | O128: 2025-01 | P128: Yes | Q128: 40000
A129: ORD00128 | B129: 45767 | C129: CUST0336 | D129: P054 | E129: 3 | F129: 100000 | G129: 300000 | H129: NEWUSER | I129: 30000 | J129: 30000 | K129: 300000 | L129: E-Wallet | M129: JNE | N129: Delivered | O129: 2025-04 | P129: Yes | Q129: 270000
A130: ORD00129 | B130: 45774 | C130: CUST0025 | D130: P015 | E130: 2 | F130: 500000 | G130: 1000000 | H130: NONE | I130: 0 | J130: 30000 | K130: 1030000 | L130: Credit Card | M130: AnterAja | N130: Delivered | O130: 2025-04 | P130: Yes | Q130: 1000000
A131: ORD00130 | B131: 45688 | C131: CUST0334 | D131: P020 | E131: 1 | F131: 75000 | G131: 75000 | H131: NONE | I131: 0 | J131: 15000 | K131: 90000 | L131: COD | N131: Delivered | O131: 2025-01 | P131: Yes | Q131: 75000
A132: ORD00131 | B132: 45717 | C132: CUST0151 | D132: P019 | E132: 4 | F132: 500000 | G132: 2000000 | H132: NONE | I132: 0 | J132: 20000 | K132: 2020000 | L132: Credit Card | M132: J&T | N132: Delivered | O132: 2025-03 | P132: Yes | Q132: 2000000
A133: ORD00132 | B133: 45835 | C133: CUST0253 | D133: P031 | E133: 4 | F133: 150000 | G133: 600000 | H133: NONE | I133: 0 | J133: 25000 | K133: 625000 | L133: Bank Transfer | M133: SiCepat | N133: Returned | O133: 2025-06 | P133: No | Q133: 600000
A134: ORD00133 | B134: 45772 | C134: CUST0263 | D134: P016 | E134: 2 | F134: 150000 | G134: 300000 | H134: NEWUSER | I134: 30000 | J134: 25000 | K134: 295000 | L134: Credit Card | M134: AnterAja | N134: Delivered | O134: 2025-04 | P134: Yes | Q134: 270000
A135: ORD00134 | B135: 45709 | C135: CUST0221 | D135: P052 | E135: 2 | F135: 200000 | G135: 400000 | H135: DISC15 | I135: 60000 | J135: 30000 | K135: 370000 | L135: E-Wallet | M135: SiCepat | N135: Delivered | O135: 2025-02 | P135: Yes | Q135: 340000
A136: ORD00135 | B136: 45664 | C136: CUST0155 | D136: P028 | E136: 3 | F136: 50000 | G136: 150000 | H136: FLASHSALE | I136: 30000 | J136: 15000 | K136: 135000 | L136: Credit Card | M136: J&T | N136: Processing | O136: 2025-01 | P136: No | Q136: 120000
A137: ORD00136 | B137: 45719 | C137: CUST0219 | D137: P021 | E137: 3 | F137: 200000 | G137: 600000 | H137: NONE | I137: 0 | J137: 30000 | K137: 630000 | L137: E-Wallet | M137: SiCepat | N137: Shipped | O137: 2025-03 | P137: No | Q137: 600000
A138: ORD00137 | B138: 45722 | C138: CUST0013 | D138: P021 | E138: 1 | F138: 200000 | G138: 200000 | H138: NONE | I138: 0 | J138: 25000 | K138: 225000 | L138: COD | M138: J&T | N138: Delivered | O138: 2025-03 | P138: Yes | Q138: 200000
A139: ORD00138 | B139: 45796 | C139: CUST0191 | D139: P021 | E139: 2 | F139: 200000 | G139: 400000 | H139: NONE | I139: 0 | J139: 25000 | K139: 425000 | L139: Bank Transfer | M139: J&T | N139: Delivered | O139: 2025-05 | P139: Yes | Q139: 400000
A140: ORD00139 | B140: 45769 | C140: CUST0252 | D140: P018 | E140: 1 | F140: 500000 | G140: 500000 | I140: 0 | J140: 15000 | K140: 515000 | L140: E-Wallet | M140: J&T | N140: Delivered | O140: 2025-04 | P140: Yes | Q140: 500000
A141: ORD00140 | B141: 45798 | C141: CUST0113 | D141: P041 | E141: 1 | F141: 75000 | G141: 75000 | H141: NONE | I141: 0 | J141: 30000 | K141: 105000 | L141: COD | M141: J&T | N141: Delivered | O141: 2025-05 | P141: Yes | Q141: 75000
A142: ORD00141 | B142: 45754 | C142: CUST0010 | D142: P050 | E142: 1 | F142: 200000 | G142: 200000 | H142: DISC10 | I142: 20000 | J142: 15000 | K142: 195000 | L142: Credit Card | M142: AnterAja | N142: Delivered | O142: 2025-04 | P142: Yes | Q142: 180000
A143: ORD00142 | B143: 45665 | C143: CUST0214 | D143: P008 | E143: 1 | F143: 150000 | G143: 150000 | H143: NEWUSER | I143: 15000 | J143: 30000 | K143: 165000 | L143: Bank Transfer | M143: AnterAja | N143: Delivered | O143: 2025-01 | P143: Yes | Q143: 135000
A144: ORD00143 | B144: 45817 | C144: CUST0087 | D144: P037 | E144: 2 | F144: 100000 | G144: 200000 | H144: NONE | I144: 0 | J144: 20000 | K144: 220000 | L144: Credit Card | M144: JNE | N144: Delivered | O144: 2025-06 | P144: Yes | Q144: 200000
A145: ORD00144 | B145: 45809 | C145: CUST0017 | D145: P005 | E145: 2 | F145: 75000 | G145: 150000 | H145: FLASHSALE | I145: 30000 | J145: 25000 | K145: 145000 | L145: E-Wallet | M145: J&T | N145: Shipped | O145: 2025-06 | P145: No | Q145: 120000
A146: ORD00145 | B146: 45800 | C146: CUST0211 | D146: P007 | E146: 1 | F146: 150000 | G146: 150000 | H146: DISC10 | I146: 15000 | J146: 15000 | K146: 150000 | L146: Bank Transfer | M146: JNE | N146: Delivered | O146: 2025-05 | P146: Yes | Q146: 135000
A147: ORD00146 | B147: 45695 | C147: CUST0111 | D147: P032 | E147: 2 | F147: 35000 | G147: 70000 | H147: DISC10 | I147: 7000 | J147: 15000 | K147: 78000 | L147: Credit Card | M147: AnterAja | N147: Cancelled | O147: 2025-02 | P147: No | Q147: 63000
A148: ORD00147 | B148: 45835 | C148: CUST0049 | D148: P036 | E148: 3 | F148: 150000 | G148: 450000 | H148: DISC10 | I148: 45000 | J148: 15000 | K148: 420000 | L148: Bank Transfer | M148: JNE | N148: Delivered | O148: 2025-06 | P148: Yes | Q148: 405000
A149: ORD00148 | B149: 45667 | C149: CUST0149 | D149: P036 | E149: 2 | F149: 150000 | G149: 300000 | H149: DISC10 | I149: 30000 | J149: 25000 | K149: 295000 | L149: Bank Transfer | M149: JNE | N149: Delivered | O149: 2025-01 | P149: Yes | Q149: 270000
A150: ORD00149 | B150: 45668 | C150: CUST0010 | D150: P015 | E150: 1 | F150: 500000 | G150: 500000 | H150: NONE | I150: 0 | J150: 25000 | K150: 525000 | L150: Bank Transfer | M150: JNE | N150: Cancelled | O150: 2025-01 | P150: No | Q150: 500000
A151: ORD00150 | B151: 45771 | C151: CUST0278 | D151: P052 | E151: 3 | F151: 200000 | G151: 600000 | H151: NEWUSER | I151: 60000 | J151: 30000 | K151: 570000 | L151: Credit Card | M151: SiCepat | N151: Cancelled | O151: 2025-04 | P151: No | Q151: 540000
...

Sheet customers
A1: customer_id | B1: customer_name | C1: gender | D1: city | E1: customer_segment
A2: CUST0001 | B2: Dinda Utami | C2: Male | D2: Surabaya | E2: Bronze
A3: CUST0002 | B3: Kevin Rizki Pangestu Mahendra | C3: Male | D3: Depok | E3: Bronze
A4: CUST0003 | B4: Sania Maulana | C4: Male | D4: Surabaya | E4: Gold
A5: CUST0004 | B5: Nisa Salim | C5: Male | D5: Depok | E5: Gold
A6: CUST0005 | B6: Kiki Galang Suryanto | C6: Male | D6: Bandung | E6: Bronze
A7: CUST0006 | B7: Fauzan Utami | C7: Female | D7: Bandung | E7: Silver
A8: CUST0007 | B8: Irene Dwi Prasetyo | C8: Female | D8: Bandung | E8: Bronze
A9: CUST0008 | B9: Rani Handayani | C9: Male | D9: Solo | E9: Bronze
A10: CUST0009 | B10: Mira Putri Pranoto Herlambang | C10: Female | D10: Surabaya | E10: Bronze
A11: CUST0010 | B11: Olivia Lestari | C11: Female | D11: Depok | E11: Bronze
A12: CUST0011 | B12: Indra Pranoto | C12: Female | D12: Semarang | E12: Silver
... A351: CUST0350 | B351: Nabila Utami | C351: Female | D351: Malang | E351: Bronze

Sheet products
A1: product_id | B1: product_name | C1: category | D1: brand | E1: unit_price
A2: P001 | B2: Headphone Wireless Noise Cancelling | C2: Electronics | D2: Atech | E2: 300000
A3: P002 | B3: Kemeja Casual Slim Fit | C3: Fashion | D3: Modest | E3: 100000
A4: P003 | B4: Sprei Katun Jepang Soft | C4: Home | D4: Casa | E4: 150000
A5: P004 | B5: Serum Wajah Brightening Vitamin C | C5: Beauty | D5: GlowUp | E5: 300000
A6: P005 | B6: Matras Yoga Anti Slip TPE | C6: Sports | D6: Active | E6: 75000
A7: P006 | B7: Buku Panduan Bisnis & Strategi Modern | C7: Books | D7: Insight | E7: 500000
A8: P007 | B8: Earphone Bluetooth TWS Pro | C8: Electronics | D8: Atech | E8: 150000
A9: P008 | B9: Kaos Polos Cotton Combed 30s | C9: Fashion | D9: Modest | E9: 150000
A10: P009 | B10: Bantal Leher Memory Foam | C10: Home | D10: Casa | E10: 300000
A11: P010 | B11: Facial Wash Foam Mild Cleanser | C11: Beauty | D11: GlowUp | E11: 50000
A12: P011 | B12: Dumbbell Neoprene Set 2kg | C12: Sports | D12: Active | E12: 75000
A13: P012 | B13: Buku Self Development Master Mindset | C13: Books | D13: Insight | E13: 300000
... A61: P060 | B61: Buku Sejarah & Peradaban Dunia | C61: Books | D61: Insight | E61: 150000
